<robot name='robot'>
	<material name='blue'>
		<color rgba='0 0 0.8 1'/>
	</material>
	<material name='red'>
		<color rgba='0.8 0 0 1'/>
	</material>
	<link name='a0'>
		<visual>
			<origin rpy='0.0 0.0 0.0' xyz='0.0 0.0 0.0'/>
			<geometry>
				<cylinder length='1' radius='0.5'/>
			</geometry>
			<material name='blue'/>
		</visual>
	</link>
	<link name='l0'>
		<visual>
			<origin rpy='0.0 1.5707963267948966 0.0' xyz='0.0445795 0.0 0.0'/>
			<geometry>
				<cylinder length='0.089159' radius='0.4'/>
			</geometry>
			<material name='red'/>
		</visual>
	</link>
	<joint name='move_l0_from_a0' type='continuous'>
		<parent link='a0'/>
		<child link='l0'/>
		<axis xyz='0.0 0.0 1.0'/>
		<origin rpy='0 0 0' xyz='0.0 0.0 0.0'/>
	</joint>
	<link name='a1'>
		<visual>
			<origin rpy='1.5707963267948966 0.0 0.0' xyz='0.089159 0.0 0.0'/>
			<geometry>
				<cylinder length='1' radius='0.5'/>
			</geometry>
			<material name='blue'/>
		</visual>
	</link>
	<joint name='fix_a1_to_l0' type='fixed'>
		<parent link='l0'/>
		<child link='a1'/>
		<origin rpy='0 0 0' xyz='0 0 0'/>
	</joint>
	<link name='l1'>
		<visual>
			<origin rpy='0.0 0.0 0.0' xyz='0.0 0.0 -0.2125'/>
			<geometry>
				<cylinder length='0.425' radius='0.4'/>
			</geometry>
			<material name='red'/>
		</visual>
	</link>
	<joint name='move_l1_from_a1' type='continuous'>
		<parent link='a1'/>
		<child link='l1'/>
		<axis xyz='0.0 -1.0 6.123233995736766e-17'/>
		<origin rpy='0 0 0' xyz='0.089159 0.0 0.0'/>
	</joint>
	<link name='a2'>
		<visual>
			<origin rpy='1.5707963267948966 0.0 0.0' xyz='0.0 0.0 -0.425'/>
			<geometry>
				<cylinder length='1' radius='0.5'/>
			</geometry>
			<material name='blue'/>
		</visual>
	</link>
	<joint name='fix_a2_to_l1' type='fixed'>
		<parent link='l1'/>
		<child link='a2'/>
		<origin rpy='0 0 0' xyz='0 0 0'/>
	</joint>
	<link name='l2'>
		<visual>
			<origin rpy='3.141592653589793 1.3150237616323175 -3.141592653589793' xyz='0.75 0.0 -0.196125'/>
			<geometry>
				<cylinder length='1.5504386677647073' radius='0.4'/>
			</geometry>
			<material name='red'/>
		</visual>
	</link>
	<joint name='move_l2_from_a2' type='continuous'>
		<parent link='a2'/>
		<child link='l2'/>
		<axis xyz='0.0 -1.0 6.123233995736766e-17'/>
		<origin rpy='0 0 0' xyz='0.0 0.0 -0.425'/>
	</joint>
	<link name='a3'>
		<visual>
			<origin rpy='1.5707963267948966 0.0 0.0' xyz='1.5 0.0 -0.39225'/>
			<geometry>
				<cylinder length='1' radius='0.5'/>
			</geometry>
			<material name='blue'/>
		</visual>
	</link>
	<joint name='fix_a3_to_l2' type='fixed'>
		<parent link='l2'/>
		<child link='a3'/>
		<origin rpy='0 0 0' xyz='0 0 0'/>
	</joint>
	<link name='l3'>
		<visual>
			<origin rpy='0.0 1.5707963267948966 0.0' xyz='0.054575 0.0 0.0'/>
			<geometry>
				<cylinder length='0.10915' radius='0.4'/>
			</geometry>
			<material name='red'/>
		</visual>
	</link>
	<joint name='move_l3_from_a3' type='continuous'>
		<parent link='a3'/>
		<child link='l3'/>
		<axis xyz='0.0 -1.0 6.123233995736766e-17'/>
		<origin rpy='0 0 0' xyz='1.5 0.0 -0.39225'/>
	</joint>
	<link name='a4'>
		<visual>
			<origin rpy='3.141592653589793 0.0 0.0' xyz='0.10915 0.0 0.0'/>
			<geometry>
				<cylinder length='1' radius='0.5'/>
			</geometry>
			<material name='blue'/>
		</visual>
	</link>
	<joint name='fix_a4_to_l3' type='fixed'>
		<parent link='l3'/>
		<child link='a4'/>
		<origin rpy='0 0 0' xyz='0 0 0'/>
	</joint>
	<link name='l4'>
		<visual>
			<origin rpy='0.0 1.5707963267948966 0.0' xyz='0.047325 0.0 0.0'/>
			<geometry>
				<cylinder length='0.09465' radius='0.4'/>
			</geometry>
			<material name='red'/>
		</visual>
	</link>
	<joint name='move_l4_from_a4' type='continuous'>
		<parent link='a4'/>
		<child link='l4'/>
		<axis xyz='0.0 -1.2246467991473532e-16 -1.0'/>
		<origin rpy='0 0 0' xyz='0.10915 0.0 0.0'/>
	</joint>
	<link name='a5'>
		<visual>
			<origin rpy='1.5707963267948966 0.0 0.0' xyz='0.09465 0.0 0.0'/>
			<geometry>
				<cylinder length='1' radius='0.5'/>
			</geometry>
			<material name='blue'/>
		</visual>
	</link>
	<joint name='fix_a5_to_l4' type='fixed'>
		<parent link='l4'/>
		<child link='a5'/>
		<origin rpy='0 0 0' xyz='0 0 0'/>
	</joint>
	<link name='l5'>
		<visual>
			<origin rpy='0.0 1.5707963267948966 0.0' xyz='0.04115 0.0 0.0'/>
			<geometry>
				<cylinder length='0.0823' radius='0.4'/>
			</geometry>
			<material name='red'/>
		</visual>
	</link>
	<joint name='move_l5_from_a5' type='continuous'>
		<parent link='a5'/>
		<child link='l5'/>
		<axis xyz='0.0 -1.0 6.123233995736766e-17'/>
		<origin rpy='0 0 0' xyz='0.09465 0.0 0.0'/>
	</joint>
</robot>
